Workbook

Sheet Lisez-moi
B2: Humatiq · projection financière sur 3 ans
B3: Trois scénarios (prudent, central, ambitieux) sur trois années, pour tester si le modèle est viable.
B5: Comment l'utiliser
B6: 1. Onglet « Hypothèses » : les cellules jaunes sont à ajuster (prix, temps passé, charges, volumes vendus par an).
B7: 2. Onglet « Projection » : tout se calcule (chiffre d'affaires par activité, charges, cotisations, revenu, jours de travail).
B8: 3. Onglet « Synthèse » : les chiffres clés et le graphique à comparer d'un scénario à l'autre.
B10: Ce qu'il faut garder en tête
B11: Les volumes sont des hypothèses de travail, pas des prévisions. Remplacez-les par vos chiffres dès les premiers clients.
B12: Le taux de cotisations (25 %) est une approximation pour une micro-entreprise de prestations de services : vérifiez-le avec votre comptable ou l'URSSAF.
B13: Le plafond de chiffre d'affaires de la micro-entreprise pour les services (83 600 € en 2026, source : lefreelance.fr) est signalé : au-delà, il faut changer de statut.
B14: La TVA n'est pas modélisée : prix considérés hors taxe, en franchise de TVA tant que le seuil n'est pas dépassé.
B15: La ligne « Jours de travail » compare le temps nécessaire aux jours disponibles : si elle dépasse, le scénario n'est pas tenable sans partenaires.
B16: Ce document n'est pas un conseil financier ou comptable.

Sheet Synthèse
B2: Synthèse
B3: Les chiffres clés par scénario. Lecture : Année 1 à Année 3.
C5: Prudent | F5: Central | I5: Ambitieux
C6: A1 | D6: A2 | E6: A3 | F6: A1 | G6: A2 | H6: A3 | I6: A1 | J6: A2 | K6: A3
B7: Chiffre d'affaires | C7: =Projection!C18 -> 23074 | D7: =Projection!D18 -> 50690 | E7: =Projection!E18 -> 75704 | F7: =Projection!F18 -> 51054 | G7: =Projection!G18 -> 100560 | H7: =Projection!H18 -> 149592 | I7: =Projection!I18 -> 85490 | J7: =Projection!J18 -> 160440 | K7: =Projection!K18 -> 237280
B8: Revenu net avant impôt | C8: =Projection!C31 -> 13853.28 | D8: =Projection!D31 -> 32916.8 | E8: =Projection!E31 -> 48906.88 | F8: =Projection!F31 -> 33178.88 | G8: =Projection!G31 -> 66383.2 | H8: =Projection!H31 -> 101066.24 | I8: =Projection!I31 -> 57152.8 | J8: =Projection!J31 -> 108276.8 | K8: =Projection!K31 -> 162621.6
B9: Revenu net par mois | C9: =Projection!C32 -> 1154.44 | D9: =Projection!D32 -> 2743.0667 | E9: =Projection!E32 -> 4075.5733 | F9: =Projection!F32 -> 2764.9067 | G9: =Projection!G32 -> 5531.9333 | H9: =Projection!H32 -> 8422.1867 | I9: =Projection!I32 -> 4762.7333 | J9: =Projection!J32 -> 9023.0667 | K9: =Projection!K32 -> 13551.8
B10: Dont commissions du réseau | C10: =Projection!C17 -> 0 | D10: =Projection!D17 -> 2610 | E10: =Projection!E17 -> 6960 | F10: =Projection!F17 -> 870 | G10: =Projection!G17 -> 6960 | H10: =Projection!H17 -> 17400 | I10: =Projection!I17 -> 2610 | J10: =Projection!J17 -> 17400 | K10: =Projection!K17 -> 39150
B11: Missions réalisées par le réseau | C11: =Projection!C19 -> 0 | D11: =Projection!D19 -> 17400 | E11: =Projection!E19 -> 46400 | F11: =Projection!F19 -> 5800 | G11: =Projection!G19 -> 46400 | H11: =Projection!H19 -> 116000 | I11: =Projection!I19 -> 17400 | J11: =Projection!J19 -> 116000 | K11: =Projection!K19 -> 261000
B12: Jours de travail | C12: =Projection!C37 -> 39 | D12: =Projection!D37 -> 81.5 | E12: =Projection!E37 -> 115 | F12: =Projection!F37 -> 78 | G12: =Projection!G37 -> 143.5 | H12: =Projection!H37 -> 206 | I12: =Projection!I37 -> 121.5 | J12: =Projection!J37 -> 213.5 | K12: =Projection!K37 -> 302
B13: Taux d'occupation | C13: =Projection!C38 -> 0.325 | D13: =Projection!D38 -> 0.67916667 | E13: =Projection!E38 -> 0.95833333 | F13: =Projection!F38 -> 0.65 | G13: =Projection!G38 -> 1.1958333 | H13: =Projection!H38 -> 1.7166667 | I13: =Projection!I38 -> 1.0125 | J13: =Projection!J38 -> 1.7791667 | K13: =Projection!K38 -> 2.5166667
B14: Plafond micro dépassé ? | C14: =Projection!C40 -> Non | D14: =Projection!D40 -> Non | E14: =Projection!E40 -> Non | F14: =Projection!F40 -> Non | G14: =Projection!G40 -> Oui : changer de statut | H14: =Projection!H40 -> Oui : changer de statut | I14: =Projection!I40 -> Oui : changer de statut | J14: =Projection!J40 -> Oui : changer de statut | K14: =Projection!K40 -> Oui : changer de statut
B17: Chiffre d'affaires par année
B18: Année | C18: Prudent | D18: Central | E18: Ambitieux
B19: Année 1 | C19: =Projection!C18 -> 23074 | D19: =Projection!F18 -> 51054 | E19: =Projection!I18 -> 85490
B20: Année 2 | C20: =Projection!D18 -> 50690 | D20: =Projection!G18 -> 100560 | E20: =Projection!J18 -> 160440
B21: Année 3 | C21: =Projection!E18 -> 75704 | D21: =Projection!H18 -> 149592 | E21: =Projection!K18 -> 237280

Sheet Hypothèses
B2: Hypothèses
B3: Cellules jaunes : à ajuster. Prix hors taxe.
B5: Offre | C5: Prix HT (€) | D5: Jours de travail | M5: Commentaire
B6: Diagnostic seul | C6: 990 | D6: 1.5 | M6: Demi-journée sur site + analyse et rapport
B7: Pack Démarrage | C7: 2900 | D7: 5 | M7: Diagnostic + 3 automatisations + prise en main
B8: Automatisation à l'unité (prix moyen) | C8: 900 | D8: 1.5 | M8: Entre 600 € (simple) et 1 500 € (avancée)
B9: Suivi mensuel (par client et par mois) | C9: 120 | D9: 0.25 | M9: Surveillance, corrections, petites évolutions
B10: Atelier Repérer 3 h (groupe) | C10: 690 | D10: 0.75 | M10: Préparation comprise
B11: Formation 1 jour (groupe) | C11: 1290 | D11: 1.75 | M11: Préparation comprise
B12: Formation 2 jours (groupe) | C12: 2290 | D12: 3.25 | M12: Préparation comprise
B13: Masterclass 2 h (par participant) | C13: 49 | D13: 0 | M13: Temps compté par session plus bas
B14: Parcours Intégrateur (par participant) | C14: 690 | D14: 0 | M14: Temps compté par cohorte plus bas
B15: Mission confiée à un partenaire (valeur moyenne) | C15: 2900 | D15: 0 | M15: Facturée par le partenaire
B17: Paramètres | C17: Valeur | M17: Commentaire
B18: Jours par masterclass (préparation comprise) | C18: 0.75
B19: Jours par cohorte du Parcours Intégrateur | C19: 6 | M19: 6 sessions + corrections
B20: Jours de suivi par partenaire actif et par an | C20: 2 | M20: Qualité, relectures, appui
B21: Commission sur les missions des partenaires | C21: 0.15 | M21: Les apporteurs prennent souvent 5 à 12 %
B22: Jours facturables disponibles par an | C22: 120 | M22: Environ 10 jours par mois, à côté de SowlSafe
B23: Taux de cotisations sociales (approximation) | C23: 0.25 | M23: À vérifier : URSSAF / comptable
B24: Outils numériques (€ par mois) | C24: 60 | M24: Make, Google Workspace, nom de domaine…
B25: Assurance RC Pro, banque, comptable (€ par an) | C25: 1200
B26: Marketing (part du chiffre d'affaires) | C26: 0.03 | M26: Salons, publicité, supports
B27: Déplacements (€ par jour sur site) | C27: 40 | M27: Appliqué aux diagnostics, packs et formations
B28: Qualiopi : audit initial (€) | C28: 1200 | M28: Indépendant : 600 à 1 200 € HT (kaliopi.io)
B29: Qualiopi : coût annuel ensuite (€) | C29: 600 | M29: Audit de surveillance tous les 18 mois
B30: Plafond micro-entreprise services (€) | C30: 83600 | M30: Valeur 2026, source lefreelance.fr
B33: Volumes vendus par an
C34: Prudent | F34: Central | I34: Ambitieux
C35: Année 1 | D35: Année 2 | E35: Année 3 | F35: Année 1 | G35: Année 2 | H35: Année 3 | I35: Année 1 | J35: Année 2 | K35: Année 3
B36: Diagnostics vendus seuls | C36: 4 | D36: 6 | E36: 8 | F36: 6 | G36: 10 | H36: 12 | I36: 8 | J36: 12 | K36: 15
B37: Packs Démarrage | C37: 2 | D37: 4 | E37: 6 | F37: 4 | G37: 7 | H37: 10 | I37: 6 | J37: 10 | K37: 14
B38: Automatisations à l'unité | C38: 3 | D38: 5 | E38: 6 | F38: 5 | G38: 8 | H38: 10 | I38: 8 | J38: 12 | K38: 15
B39: Suivi : nombre de mois-clients | C39: 12 | D39: 36 | E39: 60 | F39: 24 | G39: 72 | H39: 120 | I39: 48 | J39: 120 | K39: 200
B40: Ateliers Repérer 3 h | C40: 2 | D40: 3 | E40: 4 | F40: 3 | G40: 5 | H40: 6 | I40: 4 | J40: 6 | K40: 8
B41: Formations 1 jour | C41: 2 | D41: 4 | E41: 6 | F41: 4 | G41: 7 | H41: 10 | I41: 6 | J41: 10 | K41: 14
B42: Formations 2 jours | C42: 0 | D42: 1 | E42: 2 | F42: 1 | G42: 2 | H42: 4 | I42: 2 | J42: 4 | K42: 6
B43: Masterclass (sessions) | C43: 6 | D43: 10 | E43: 12 | F43: 12 | G43: 20 | H43: 24 | I43: 18 | J43: 30 | K43: 36
B44: Participants par masterclass | C44: 6 | D44: 8 | E44: 8 | F44: 8 | G44: 10 | H44: 12 | I44: 10 | J44: 12 | K44: 15
B45: Cohortes du Parcours Intégrateur | C45: 1 | D45: 2 | E45: 2 | F45: 2 | G45: 3 | H45: 4 | I45: 3 | J45: 4 | K45: 5
...

Sheet Projection
B2: Projection
B3: Tout est calculé à partir de l'onglet Hypothèses.
C5: Prudent | F5: Central | I5: Ambitieux
C6: Année 1 | D6: Année 2 | E6: Année 3 | F6: Année 1 | G6: Année 2 | H6: Année 3 | I6: Année 1 | J6: Année 2 | K6: Année 3
B9: Chiffre d'affaires
B10: Diagnostics | C10: =Hypothèses!C36*Hypothèses!$C$6 -> 3960 | D10: =Hypothèses!D36*Hypothèses!$C$6 -> 5940 | E10: =Hypothèses!E36*Hypothèses!$C$6 -> 7920 | F10: =Hypothèses!F36*Hypothèses!$C$6 -> 5940 | G10: =Hypothèses!G36*Hypothèses!$C$6 -> 9900 | H10: =Hypothèses!H36*Hypothèses!$C$6 -> 11880 | I10: =Hypothèses!I36*Hypothèses!$C$6 -> 7920 | J10: =Hypothèses!J36*Hypothèses!$C$6 -> 11880 | K10: =Hypothèses!K36*Hypothèses!$C$6 -> 14850
B11: Packs Démarrage | C11: =Hypothèses!C37*Hypothèses!$C$7 -> 5800 | D11: =Hypothèses!D37*Hypothèses!$C$7 -> 11600 | E11: =Hypothèses!E37*Hypothèses!$C$7 -> 17400 | F11: =Hypothèses!F37*Hypothèses!$C$7 -> 11600 | G11: =Hypothèses!G37*Hypothèses!$C$7 -> 20300 | H11: =Hypothèses!H37*Hypothèses!$C$7 -> 29000 | I11: =Hypothèses!I37*Hypothèses!$C$7 -> 17400 | J11: =Hypothèses!J37*Hypothèses!$C$7 -> 29000 | K11: =Hypothèses!K37*Hypothèses!$C$7 -> 40600
B12: Automatisations à l'unité | C12: =Hypothèses!C38*Hypothèses!$C$8 -> 2700 | D12: =Hypothèses!D38*Hypothèses!$C$8 -> 4500 | E12: =Hypothèses!E38*Hypothèses!$C$8 -> 5400 | F12: =Hypothèses!F38*Hypothèses!$C$8 -> 4500 | G12: =Hypothèses!G38*Hypothèses!$C$8 -> 7200 | H12: =Hypothèses!H38*Hypothèses!$C$8 -> 9000 | I12: =Hypothèses!I38*Hypothèses!$C$8 -> 7200 | J12: =Hypothèses!J38*Hypothèses!$C$8 -> 10800 | K12: =Hypothèses!K38*Hypothèses!$C$8 -> 13500
B13: Suivi mensuel | C13: =Hypothèses!C39*Hypothèses!$C$9 -> 1440 | D13: =Hypothèses!D39*Hypothèses!$C$9 -> 4320 | E13: =Hypothèses!E39*Hypothèses!$C$9 -> 7200 | F13: =Hypothèses!F39*Hypothèses!$C$9 -> 2880 | G13: =Hypothèses!G39*Hypothèses!$C$9 -> 8640 | H13: =Hypothèses!H39*Hypothèses!$C$9 -> 14400 | I13: =Hypothèses!I39*Hypothèses!$C$9 -> 5760 | J13: =Hypothèses!J39*Hypothèses!$C$9 -> 14400 | K13: =Hypothèses!K39*Hypothèses!$C$9 -> 24000
B14: Formations en entreprise | C14: =Hypothèses!C40*Hypothèses!$C$10+Hypothèses!C41*Hypothèses!$C$11+Hypothèses!C42*Hypothèses!$C$12 -> 3960 | D14: =Hypothèses!D40*Hypothèses!$C$10+Hypothèses!D41*Hypothèses!$C$11+Hypothèses!D42*Hypothèses!$C$12 -> 9520 | E14: =Hypothèses!E40*Hypothèses!$C$10+Hypothèses!E41*Hypothèses!$C$11+Hypothèses!E42*Hypothèses!$C$12 -> 15080 | F14: =Hypothèses!F40*Hypothèses!$C$10+Hypothèses!F41*Hypothèses!$C$11+Hypothèses!F42*Hypothèses!$C$12 -> 9520 | G14: =Hypothèses!G40*Hypothèses!$C$10+Hypothèses!G41*Hypothèses!$C$11+Hypothèses!G42*Hypothèses!$C$12 -> 17060 | H14: =Hypothèses!H40*Hypothèses!$C$10+Hypothèses!H41*Hypothèses!$C$11+Hypothèses!H42*Hypothèses!$C$12 -> 26200 | I14: =Hypothèses!I40*Hypothèses!$C$10+Hypothèses!I41*Hypothèses!$C$11+Hypothèses!I42*Hypothèses!$C$12 -> 15080 | J14: =Hypothèses!J40*Hypothèses!$C$10+Hypothèses!J41*Hypothèses!$C$11+Hypothèses!J42*Hypothèses!$C$12 -> 26200 | K14: =Hypothèses!K40*Hypothèses!$C$10+Hypothèses!K41*Hypothèses!$C$11+Hypothèses!K42*Hypothèses!$C$12 -> 37320
B15: Masterclass | C15: =Hypothèses!C43*Hypothèses!C44*Hypothèses!$C$13 -> 1764 | D15: =Hypothèses!D43*Hypothèses!D44*Hypothèses!$C$13 -> 3920 | E15: =Hypothèses!E43*Hypothèses!E44*Hypothèses!$C$13 -> 4704 | F15: =Hypothèses!F43*Hypothèses!F44*Hypothèses!$C$13 -> 4704 | G15: =Hypothèses!G43*Hypothèses!G44*Hypothèses!$C$13 -> 9800 | H15: =Hypothèses!H43*Hypothèses!H44*Hypothèses!$C$13 -> 14112 | I15: =Hypothèses!I43*Hypothèses!I44*Hypothèses!$C$13 -> 8820 | J15: =Hypothèses!J43*Hypothèses!J44*Hypothèses!$C$13 -> 17640 | K15: =Hypothèses!K43*Hypothèses!K44*Hypothèses!$C$13 -> 26460
B16: Parcours Intégrateur | C16: =Hypothèses!C45*Hypothèses!C46*Hypothèses!$C$14 -> 3450 | D16: =Hypothèses!D45*Hypothèses!D46*Hypothèses!$C$14 -> 8280 | E16: =Hypothèses!E45*Hypothèses!E46*Hypothèses!$C$14 -> 11040 | F16: =Hypothèses!F45*Hypothèses!F46*Hypothèses!$C$14 -> 11040 | G16: =Hypothèses!G45*Hypothèses!G46*Hypothèses!$C$14 -> 20700 | H16: =Hypothèses!H45*Hypothèses!H46*Hypothèses!$C$14 -> 27600 | I16: =Hypothèses!I45*Hypothèses!I46*Hypothèses!$C$14 -> 20700 | J16: =Hypothèses!J45*Hypothèses!J46*Hypothèses!$C$14 -> 33120 | K16: =Hypothèses!K45*Hypothèses!K46*Hypothèses!$C$14 -> 41400
B17: Commissions sur le réseau | C17: =Hypothèses!C47*Hypothèses!C48*Hypothèses!$C$15*Hypothèses!$C$21 -> 0 | D17: =Hypothèses!D47*Hypothèses!D48*Hypothèses!$C$15*Hypothèses!$C$21 -> 2610 | E17: =Hypothèses!E47*Hypothèses!E48*Hypothèses!$C$15*Hypothèses!$C$21 -> 6960 | F17: =Hypothèses!F47*Hypothèses!F48*Hypothèses!$C$15*Hypothèses!$C$21 -> 870 | G17: =Hypothèses!G47*Hypothèses!G48*Hypothèses!$C$15*Hypothèses!$C$21 -> 6960 | H17: =Hypothèses!H47*Hypothèses!H48*Hypothèses!$C$15*Hypothèses!$C$21 -> 17400 | I17: =Hypothèses!I47*Hypothèses!I48*Hypothèses!$C$15*Hypothèses!$C$21 -> 2610 | J17: =Hypothèses!J47*Hypothèses!J48*Hypothèses!$C$15*Hypothèses!$C$21 -> 17400 | K17: =Hypothèses!K47*Hypothèses!K48*Hypothèses!$C$15*Hypothèses!$C$21 -> 39150
B18: Chiffre d'affaires total | C18: =SUM(C10:C17) -> 23074 | D18: =SUM(D10:D17) -> 50690 | E18: =SUM(E10:E17) -> 75704 | F18: =SUM(F10:F17) -> 51054 | G18: =SUM(G10:G17) -> 100560 | H18: =SUM(H10:H17) -> 149592 | I18: =SUM(I10:I17) -> 85490 | J18: =SUM(J10:J17) -> 160440 | K18: =SUM(K10:K17) -> 237280
B19: Pour info : missions réalisées par le réseau (CA des partenaires) | C19: =Hypothèses!C47*Hypothèses!C48*Hypothèses!$C$15 -> 0 | D19: =Hypothèses!D47*Hypothèses!D48*Hypothèses!$C$15 -> 17400 | E19: =Hypothèses!E47*Hypothèses!E48*Hypothèses!$C$15 -> 46400 | F19: =Hypothèses!F47*Hypothèses!F48*Hypothèses!$C$15 -> 5800 | G19: =Hypothèses!G47*Hypothèses!G48*Hypothèses!$C$15 -> 46400 | H19: =Hypothèses!H47*Hypothèses!H48*Hypothèses!$C$15 -> 116000 | I19: =Hypothèses!I47*Hypothèses!I48*Hypothèses!$C$15 -> 17400 | J19: =Hypothèses!J47*Hypothèses!J48*Hypothèses!$C$15 -> 116000 | K19: =Hypothèses!K47*Hypothèses!K48*Hypothèses!$C$15 -> 261000
B21: Charges
B22: Outils numériques | C22: =Hypothèses!$C$24*12 -> 720 | D22: =Hypothèses!$C$24*12 -> 720 | E22: =Hypothèses!$C$24*12 -> 720 | F22: =Hypothèses!$C$24*12 -> 720 | G22: =Hypothèses!$C$24*12 -> 720 | H22: =Hypothèses!$C$24*12 -> 720 | I22: =Hypothèses!$C$24*12 -> 720 | J22: =Hypothèses!$C$24*12 -> 720 | K22: =Hypothèses!$C$24*12 -> 720
B23: Assurance, banque, comptable | C23: =Hypothèses!$C$25 -> 1200 | D23: =Hypothèses!$C$25 -> 1200 | E23: =Hypothèses!$C$25 -> 1200 | F23: =Hypothèses!$C$25 -> 1200 | G23: =Hypothèses!$C$25 -> 1200 | H23: =Hypothèses!$C$25 -> 1200 | I23: =Hypothèses!$C$25 -> 1200 | J23: =Hypothèses!$C$25 -> 1200 | K23: =Hypothèses!$C$25 -> 1200
B24: Marketing | C24: =C18*Hypothèses!$C$26 -> 692.22 | D24: =D18*Hypothèses!$C$26 -> 1520.7 | E24: =E18*Hypothèses!$C$26 -> 2271.12 | F24: =F18*Hypothèses!$C$26 -> 1531.62 | G24: =G18*Hypothèses!$C$26 -> 3016.8 | H24: =H18*Hypothèses!$C$26 -> 4487.76 | I24: =I18*Hypothèses!$C$26 -> 2564.7 | J24: =J18*Hypothèses!$C$26 -> 4813.2 | K24: =K18*Hypothèses!$C$26 -> 7118.4
B25: Déplacements | C25: =(Hypothèses!C36*Hypothèses!$D$6+Hypothèses!C37*Hypothèses!$D$7+Hypothèses!C40*Hypothèses!$D$10+Hypothèses!C41*Hypothèses!$D$11+Hypothèses!C42*Hypothèses!$D$12)*Hypothèses!$C$27 -> 840 | D25: =(Hypothèses!D36*Hypothèses!$D$6+Hypothèses!D37*Hypothèses!$D$7+Hypothèses!D40*Hypothèses!$D$10+Hypothèses!D41*Hypothèses!$D$11+Hypothèses!D42*Hypothèses!$D$12)*Hypothèses!$C$27 -> 1660 | E25: =(Hypothèses!E36*Hypothèses!$D$6+Hypothèses!E37*Hypothèses!$D$7+Hypothèses!E40*Hypothèses!$D$10+Hypothèses!E41*Hypothèses!$D$11+Hypothèses!E42*Hypothèses!$D$12)*Hypothèses!$C$27 -> 2480 | F25: =(Hypothèses!F36*Hypothèses!$D$6+Hypothèses!F37*Hypothèses!$D$7+Hypothèses!F40*Hypothèses!$D$10+Hypothèses!F41*Hypothèses!$D$11+Hypothèses!F42*Hypothèses!$D$12)*Hypothèses!$C$27 -> 1660 | G25: =(Hypothèses!G36*Hypothèses!$D$6+Hypothèses!G37*Hypothèses!$D$7+Hypothèses!G40*Hypothèses!$D$10+Hypothèses!G41*Hypothèses!$D$11+Hypothèses!G42*Hypothèses!$D$12)*Hypothèses!$C$27 -> 2900 | H25: =(Hypothèses!H36*Hypothèses!$D$6+Hypothèses!H37*Hypothèses!$D$7+Hypothèses!H40*Hypothèses!$D$10+Hypothèses!H41*Hypothèses!$D$11+Hypothèses!H42*Hypothèses!$D$12)*Hypothèses!$C$27 -> 4120 | I25: =(Hypothèses!I36*Hypothèses!$D$6+Hypothèses!I37*Hypothèses!$D$7+Hypothèses!I40*Hypothèses!$D$10+Hypothèses!I41*Hypothèses!$D$11+Hypothèses!I42*Hypothèses!$D$12)*Hypothèses!$C$27 -> 2480 | J25: =(Hypothèses!J36*Hypothèses!$D$6+Hypothèses!J37*Hypothèses!$D$7+Hypothèses!J40*Hypothèses!$D$10+Hypothèses!J41*Hypothèses!$D$11+Hypothèses!J42*Hypothèses!$D$12)*Hypothèses!$C$27 -> 4120 | K25: =(Hypothèses!K36*Hypothèses!$D$6+Hypothèses!K37*Hypothèses!$D$7+Hypothèses!K40*Hypothèses!$D$10+Hypothèses!K41*Hypothèses!$D$11+Hypothèses!K42*Hypothèses!$D$12)*Hypothèses!$C$27 -> 5700
B26: Qualiopi | C26: =IF(Hypothèses!C49=1,Hypothèses!$C$28,IF(Hypothèses!C49=2,Hypothèses!$C$29,0)) -> 0 | D26: =IF(Hypothèses!D49=1,Hypothèses!$C$28,IF(Hypothèses!D49=2,Hypothèses!$C$29,0)) -> 0 | E26: =IF(Hypothèses!E49=1,Hypothèses!$C$28,IF(Hypothèses!E49=2,Hypothèses!$C$29,0)) -> 1200 | F26: =IF(Hypothèses!F49=1,Hypothèses!$C$28,IF(Hypothèses!F49=2,Hypothèses!$C$29,0)) -> 0 | G26: =IF(Hypothèses!G49=1,Hypothèses!$C$28,IF(Hypothèses!G49=2,Hypothèses!$C$29,0)) -> 1200 | H26: =IF(Hypothèses!H49=1,Hypothèses!$C$28,IF(Hypothèses!H49=2,Hypothèses!$C$29,0)) -> 600 | I26: =IF(Hypothèses!I49=1,Hypothèses!$C$28,IF(Hypothèses!I49=2,Hypothèses!$C$29,0)) -> 0 | J26: =IF(Hypothèses!J49=1,Hypothèses!$C$28,IF(Hypothèses!J49=2,Hypothèses!$C$29,0)) -> 1200 | K26: =IF(Hypothèses!K49=1,Hypothèses!$C$28,IF(Hypothèses!K49=2,Hypothèses!$C$29,0)) -> 600
B27: Total des charges | C27: =SUM(C22:C26) -> 3452.22 | D27: =SUM(D22:D26) -> 5100.7 | E27: =SUM(E22:E26) -> 7871.12 | F27: =SUM(F22:F26) -> 5111.62 | G27: =SUM(G22:G26) -> 9036.8 | H27: =SUM(H22:H26) -> 11127.76 | I27: =SUM(I22:I26) -> 6964.7 | J27: =SUM(J22:J26) -> 12053.2 | K27: =SUM(K22:K26) -> 15338.4
B28: Cotisations sociales | C28: =C18*Hypothèses!$C$23 -> 5768.5 | D28: =D18*Hypothèses!$C$23 -> 12672.5 | E28: =E18*Hypothèses!$C$23 -> 18926 | F28: =F18*Hypothèses!$C$23 -> 12763.5 | G28: =G18*Hypothèses!$C$23 -> 25140 | H28: =H18*Hypothèses!$C$23 -> 37398 | I28: =I18*Hypothèses!$C$23 -> 21372.5 | J28: =J18*Hypothèses!$C$23 -> 40110 | K28: =K18*Hypothèses!$C$23 -> 59320
B30: Résultat
B31: Revenu net avant impôt | C31: =C18-C27-C28 -> 13853.28 | D31: =D18-D27-D28 -> 32916.8 | E31: =E18-E27-E28 -> 48906.88 | F31: =F18-F27-F28 -> 33178.88 | G31: =G18-G27-G28 -> 66383.2 | H31: =H18-H27-H28 -> 101066.24 | I31: =I18-I27-I28 -> 57152.8 | J31: =J18-J27-J28 -> 108276.8 | K31: =K18-K27-K28 -> 162621.6
B32: Soit par mois | C32: =C31/12 -> 1154.44 | D32: =D31/12 -> 2743.0667 | E32: =E31/12 -> 4075.5733 | F32: =F31/12 -> 2764.9067 | G32: =G31/12 -> 5531.9333 | H32: =H31/12 -> 8422.1867 | I32: =I31/12 -> 4762.7333 | J32: =J31/12 -> 9023.0667 | K32: =K31/12 -> 13551.8
B33: Part du CA venant du réseau | C33: =IFERROR(C17/C18,0) -> 0 | D33: =IFERROR(D17/D18,0) -> 0.051489446 | E33: =IFERROR(E17/E18,0) -> 0.091937018 | F33: =IFERROR(F17/F18,0) -> 0.01704078 | G33: =IFERROR(G17/G18,0) -> 0.069212411 | H33: =IFERROR(H17/H18,0) -> 0.11631638 | I33: =IFERROR(I17/I18,0) -> 0.030529887 | J33: =IFERROR(J17/J18,0) -> 0.10845176 | K33: =IFERROR(K17/K18,0) -> 0.16499494
B34: Part du CA récurrent (suivi) | C34: =IFERROR(C13/C18,0) -> 0.062407905 | D34: =IFERROR(D13/D18,0) -> 0.08522391 | E34: =IFERROR(E13/E18,0) -> 0.09510726 | F34: =IFERROR(F13/F18,0) -> 0.056410859 | G34: =IFERROR(G13/G18,0) -> 0.085918854 | H34: =IFERROR(H13/H18,0) -> 0.096261832 | I34: =IFERROR(I13/I18,0) -> 0.067376301 | J34: =IFERROR(J13/J18,0) -> 0.089753179 | K34: =IFERROR(K13/K18,0) -> 0.10114633
B36: Temps de travail
B37: Jours de travail nécessaires | C37: =Hypothèses!C36*Hypothèses!$D$6+Hypothèses!C37*Hypothèses!$D$7+Hypothèses!C38*Hypothèses!$D$8+Hypothèses!C39*Hypothèses!$D$9+Hypothèses!C40*Hypothèses!$D$10+Hypothèses!C41*Hypothèses!$D$11+Hypothèses!C42*Hypothèses!$D$12+Hypothèses!C43*Hypothèses!$C$18+Hypothèses!C45*Hypothèses!$C$19+Hypothèses!C47*Hypothèses!$C$20 -> 39 | D37: =Hypothèses!D36*Hypothèses!$D$6+Hypothèses!D37*Hypothèses!$D$7+Hypothèses!D38*Hypothèses!$D$8+Hypothèses!D39*Hypothèses!$D$9+Hypothèses!D40*Hypothèses!$D$10+Hypothèses!D41*Hypothèses!$D$11+Hypothèses!D42*Hypothèses!$D$12+Hypothèses!D43*Hypothèses!$C$18+Hypothèses!D45*Hypothèses!$C$19+Hypothèses!D47*Hypothèses!$C$20 -> 81.5 | E37: =Hypothèses!E36*Hypothèses!$D$6+Hypothèses!E37*Hypothèses!$D$7+Hypothèses!E38*Hypothèses!$D$8+Hypothèses!E39*Hypothèses!$D$9+Hypothèses!E40*Hypothèses!$D$10+Hypothèses!E41*Hypothèses!$D$11+Hypothèses!E42*Hypothèses!$D$12+Hypothèses!E43*Hypothèses!$C$18+Hypothèses!E45*Hypothèses!$C$19+Hypothèses!E47*Hypothèses!$C$20 -> 115 | F37: =Hypothèses!F36*Hypothèses!$D$6+Hypothèses!F37*Hypothèses!$D$7+Hypothèses!F38*Hypothèses!$D$8+Hypothèses!F39*Hypothèses!$D$9+Hypothèses!F40*Hypothèses!$D$10+Hypothèses!F41*Hypothèses!$D$11+Hypothèses!F42*Hypothèses!$D$12+Hypothèses!F43*Hypothèses!$C$18+Hypothèses!F45*Hypothèses!$C$19+Hypothèses!F47*Hypothèses!$C$20 -> 78 | G37: =Hypothèses!G36*Hypothèses!$D$6+Hypothèses!G37*Hypothèses!$D$7+Hypothèses!G38*Hypothèses!$D$8+Hypothèses!G39*Hypothèses!$D$9+Hypothèses!G40*Hypothèses!$D$10+Hypothèses!G41*Hypothèses!$D$11+Hypothèses!G42*Hypothèses!$D$12+Hypothèses!G43*Hypothèses!$C$18+Hypothèses!G45*Hypothèses!$C$19+Hypothèses!G47*Hypothèses!$C$20 -> 143.5 | H37: =Hypothèses!H36*Hypothèses!$D$6+Hypothèses!H37*Hypothèses!$D$7+Hypothèses!H38*Hypothèses!$D$8+Hypothèses!H39*Hypothèses!$D$9+Hypothèses!H40*Hypothèses!$D$10+Hypothèses!H41*Hypothèses!$D$11+Hypothèses!H42*Hypothèses!$D$12+Hypothèses!H43*Hypothèses!$C$18+Hypothèses!H45*Hypothèses!$C$19+Hypothèses!H47*Hypothèses!$C$20 -> 206 | I37: =Hypothèses!I36*Hypothèses!$D$6+Hypothèses!I37*Hypothèses!$D$7+Hypothèses!I38*Hypothèses!$D$8+Hypothèses!I39*Hypothèses!$D$9+Hypothèses!I40*Hypothèses!$D$10+Hypothèses!I41*Hypothèses!$D$11+Hypothèses!I42*Hypothèses!$D$12+Hypothèses!I43*Hypothèses!$C$18+Hypothèses!I45*Hypothèses!$C$19+Hypothèses!I47*Hypothèses!$C$20 -> 121.5 | J37: =Hypothèses!J36*Hypothèses!$D$6+Hypothèses!J37*Hypothèses!$D$7+Hypothèses!J38*Hypothèses!$D$8+Hypothèses!J39*Hypothèses!$D$9+Hypothèses!J40*Hypothèses!$D$10+Hypothèses!J41*Hypothèses!$D$11+Hypothèses!J42*Hypothèses!$D$12+Hypothèses!J43*Hypothèses!$C$18+Hypothèses!J45*Hypothèses!$C$19+Hypothèses!J47*Hypothèses!$C$20 -> 213.5 | K37: =Hypothèses!K36*Hypothèses!$D$6+Hypothèses!K37*Hypothèses!$D$7+Hypothèses!K38*Hypothèses!$D$8+Hypothèses!K39*Hypothèses!$D$9+Hypothèses!K40*Hypothèses!$D$10+Hypothèses!K41*Hypothèses!$D$11+Hypothèses!K42*Hypothèses!$D$12+Hypothèses!K43*Hypothèses!$C$18+Hypothèses!K45*Hypothèses!$C$19+Hypothèses!K47*Hypothèses!$C$20 -> 302
B38: Taux d'occupation (jours nécessaires / disponibles) | C38: =C37/Hypothèses!$C$22 -> 0.325 | D38: =D37/Hypothèses!$C$22 -> 0.67916667 | E38: =E37/Hypothèses!$C$22 -> 0.95833333 | F38: =F37/Hypothèses!$C$22 -> 0.65 | G38: =G37/Hypothèses!$C$22 -> 1.1958333 | H38: =H37/Hypothèses!$C$22 -> 1.7166667 | I38: =I37/Hypothèses!$C$22 -> 1.0125 | J38: =J37/Hypothèses!$C$22 -> 1.7791667 | K38: =K37/Hypothèses!$C$22 -> 2.5166667
B39: Chiffre d'affaires par jour travaillé | C39: =IFERROR(C18/C37,0) -> 591.64103 | D39: =IFERROR(D18/D37,0) -> 621.96319 | E39: =IFERROR(E18/E37,0) -> 658.29565 | F39: =IFERROR(F18/F37,0) -> 654.53846 | G39: =IFERROR(G18/G37,0) -> 700.76655 | H39: =IFERROR(H18/H37,0) -> 726.17476 | I39: =IFERROR(I18/I37,0) -> 703.6214 | J39: =IFERROR(J18/J37,0) -> 751.47541 | K39: =IFERROR(K18/K37,0) -> 785.69536
B40: Plafond micro-entreprise dépassé ? | C40: =IF(C18>Hypothèses!$C$30,"Oui : changer de statut","Non") -> Non | D40: =IF(D18>Hypothèses!$C$30,"Oui : changer de statut","Non") -> Non | E40: =IF(E18>Hypothèses!$C$30,"Oui : changer de statut","Non") -> Non | F40: =IF(F18>Hypothèses!$C$30,"Oui : changer de statut","Non") -> Non | G40: =IF(G18>Hypothèses!$C$30,"Oui : changer de statut","Non") -> Oui : changer de statut | H40: =IF(H18>Hypothèses!$C$30,"Oui : changer de statut","Non") -> Oui : changer de statut | I40: =IF(I18>Hypothèses!$C$30,"Oui : changer de statut","Non") -> Oui : changer de statut | J40: =IF(J18>Hypothèses!$C$30,"Oui : changer de statut","Non") -> Oui : changer de statut | K40: =IF(K18>Hypothèses!$C$30,"Oui : changer de statut","Non") -> Oui : changer de statut
